Workbook

Sheet Acompanhamento
A1: Acompanhamento da Montagem – SoBot
A2: Preencha só as células amarelas. Fluxo: 1) liste as subatividades e o tempo ideal de cada uma; 2) defina a meta de robôs; 3) informe quantas peças já estão concluídas em cada subatividade. O %, as unidades concluídas e os tempos saem sozinhos.
A3: Os quadros marcados com 'Valores de EXEMPLO' não são dados reais: substitua pelos seus. A aba 'Como funciona' explica cada conta com os números atuais.
A4: Meta: quantos robôs vamos montar (previstas) | B4: 10
A5: Robôs concluídos | B5: =B377&" de "&C377 -> 0 de 10
A6: Progresso geral (pelas tarefas) | B6: =D381 -> 0.13157895
A7: Unidades concluídas (soma das etapas) | B7: =B380&" de "&C380 -> 15 de 240
A8: Tempo que falta (h) | B8: =B383 -> 27.5
A9: Dias úteis restantes (aba Equipe) | B9: =B384 -> 3.4375
A10: Ir para o resumo final ↓
A12: 3. Montagem do Suporte de Manutenção | E12: Peso no robô | F12: =C390 -> 0.68421053 | O12: Concluído | P12: =E23 -> 0.19230769
A13: Unidades previstas | B13: =$B$4 -> 10 | E13: Unidades concluídas | F13: =IF(COUNT(E15:E22)=0,0,ROUND(MIN(E15:E22)*B13,0)) -> 1 | O13: Falta | P13: =1-P12 -> 0.80769231
A14: Subatividade | B14: Tempo ideal (min) | C14: Peso na etapa | D14: Peças concluídas | E14: % concluído | F14: Tempo total (min) | G14: Tempo que falta (min)
A15: Alinhamento | B15: 10 | C15: =IF(OR(A15="",$B$23=0),"",N(B15)/$B$23) -> 0.076923077 | D15: 5 | E15: =IF(A15="","",IF($B$13>0,MIN(1,N(D15)/$B$13),0)) -> 0.5 | F15: =IF(A15="","",N(B15)*$B$13) -> 100 | G15: =IF(A15="","",N(B15)*($B$13-MIN($B$13,N(D15)))) -> 50 | O15: Tarefas | P15: =COUNTA(A15:A22) -> 4
A16: Instalar pé | B16: 10 | C16: =IF(OR(A16="",$B$23=0),"",N(B16)/$B$23) -> 0.076923077 | D16: 5 | E16: =IF(A16="","",IF($B$13>0,MIN(1,N(D16)/$B$13),0)) -> 0.5 | F16: =IF(A16="","",N(B16)*$B$13) -> 100 | G16: =IF(A16="","",N(B16)*($B$13-MIN($B$13,N(D16)))) -> 50 | O16: Tarefas 100% | P16: =COUNTIF(E15:E22,">=1") -> 0
A17: Montar placa de manutenção | B17: 10 | C17: =IF(OR(A17="",$B$23=0),"",N(B17)/$B$23) -> 0.076923077 | D17: 5 | E17: =IF(A17="","",IF($B$13>0,MIN(1,N(D17)/$B$13),0)) -> 0.5 | F17: =IF(A17="","",N(B17)*$B$13) -> 100 | G17: =IF(A17="","",N(B17)*($B$13-MIN($B$13,N(D17)))) -> 50
A18: Instalar placa | B18: 100 | C18: =IF(OR(A18="",$B$23=0),"",N(B18)/$B$23) -> 0.76923077 | D18: 1 | E18: =IF(A18="","",IF($B$13>0,MIN(1,N(D18)/$B$13),0)) -> 0.1 | F18: =IF(A18="","",N(B18)*$B$13) -> 1000 | G18: =IF(A18="","",N(B18)*($B$13-MIN($B$13,N(D18)))) -> 900
C19: =IF(OR(A19="",$B$23=0),"",N(B19)/$B$23) | E19: =IF(A19="","",IF($B$13>0,MIN(1,N(D19)/$B$13),0)) | F19: =IF(A19="","",N(B19)*$B$13) | G19: =IF(A19="","",N(B19)*($B$13-MIN($B$13,N(D19))))
C20: =IF(OR(A20="",$B$23=0),"",N(B20)/$B$23) | E20: =IF(A20="","",IF($B$13>0,MIN(1,N(D20)/$B$13),0)) | F20: =IF(A20="","",N(B20)*$B$13) | G20: =IF(A20="","",N(B20)*($B$13-MIN($B$13,N(D20))))
C21: =IF(OR(A21="",$B$23=0),"",N(B21)/$B$23) | E21: =IF(A21="","",IF($B$13>0,MIN(1,N(D21)/$B$13),0)) | F21: =IF(A21="","",N(B21)*$B$13) | G21: =IF(A21="","",N(B21)*($B$13-MIN($B$13,N(D21))))
C22: =IF(OR(A22="",$B$23=0),"",N(B22)/$B$23) | E22: =IF(A22="","",IF($B$13>0,MIN(1,N(D22)/$B$13),0)) | F22: =IF(A22="","",N(B22)*$B$13) | G22: =IF(A22="","",N(B22)*($B$13-MIN($B$13,N(D22))))
A23: Total da etapa (progresso pelas tarefas) | B23: =SUM(B15:B22) -> 130 | E23: =IF(B23>0,SUMPRODUCT(B15:B22,E15:E22)/B23,IF(COUNT(E15:E22)=0,0,SUM(E15:E22)/COUNT(E15:E22))) -> 0.19230769 | F23: =SUM(F15:F22) -> 1300 | G23: =SUM(G15:G22) -> 1050
A24: Unidades concluídas ÷ previstas (menor nº de peças entre as subatividades) | D24: =F13&"/"&B13 -> 1/10 | E24: =IF(B13>0,MIN(1,F13/B13),0) -> 0.1
A27: 4. Alinhamento da estrutura do SoBot | E27: Peso no robô | F27: =C391 -> 0.31578947 | O27: Concluído | P27: =E38 -> 0
A28: Unidades previstas | B28: =$B$4 -> 10 | E28: Unidades concluídas | F28: =IF(COUNT(E30:E37)=0,0,ROUND(MIN(E30:E37)*B28,0)) -> 0 | O28: Falta | P28: =1-P27 -> 1
A29: Subatividade | B29: Tempo ideal (min) | C29: Peso na etapa | D29: Peças concluídas | E29: % concluído | F29: Tempo total (min) | G29: Tempo que falta (min)
A30: Posicionar a estrutura (exemplo) | B30: 15 | C30: =IF(OR(A30="",$B$38=0),"",N(B30)/$B$38) -> 0.25 | D30: 0 | E30: =IF(A30="","",IF($B$28>0,MIN(1,N(D30)/$B$28),0)) -> 0 | F30: =IF(A30="","",N(B30)*$B$28) -> 150 | G30: =IF(A30="","",N(B30)*($B$28-MIN($B$28,N(D30)))) -> 150 | O30: Tarefas | P30: =COUNTA(A30:A37) -> 3
A31: Conferir esquadro (exemplo) | B31: 25 | C31: =IF(OR(A31="",$B$38=0),"",N(B31)/$B$38) -> 0.41666667 | D31: 0 | E31: =IF(A31="","",IF($B$28>0,MIN(1,N(D31)/$B$28),0)) -> 0 | F31: =IF(A31="","",N(B31)*$B$28) -> 250 | G31: =IF(A31="","",N(B31)*($B$28-MIN($B$28,N(D31)))) -> 250 | O31: Tarefas 100% | P31: =COUNTIF(E30:E37,">=1") -> 0
A32: Apertar os parafusos (exemplo) | B32: 20 | C32: =IF(OR(A32="",$B$38=0),"",N(B32)/$B$38) -> 0.33333333 | D32: 0 | E32: =IF(A32="","",IF($B$28>0,MIN(1,N(D32)/$B$28),0)) -> 0 | F32: =IF(A32="","",N(B32)*$B$28) -> 200 | G32: =IF(A32="","",N(B32)*($B$28-MIN($B$28,N(D32)))) -> 200
C33: =IF(OR(A33="",$B$38=0),"",N(B33)/$B$38) | E33: =IF(A33="","",IF($B$28>0,MIN(1,N(D33)/$B$28),0)) | F33: =IF(A33="","",N(B33)*$B$28) | G33: =IF(A33="","",N(B33)*($B$28-MIN($B$28,N(D33))))
C34: =IF(OR(A34="",$B$38=0),"",N(B34)/$B$38) | E34: =IF(A34="","",IF($B$28>0,MIN(1,N(D34)/$B$28),0)) | F34: =IF(A34="","",N(B34)*$B$28) | G34: =IF(A34="","",N(B34)*($B$28-MIN($B$28,N(D34))))
C35: =IF(OR(A35="",$B$38=0),"",N(B35)/$B$38) | E35: =IF(A35="","",IF($B$28>0,MIN(1,N(D35)/$B$28),0)) | F35: =IF(A35="","",N(B35)*$B$28) | G35: =IF(A35="","",N(B35)*($B$28-MIN($B$28,N(D35))))
C36: =IF(OR(A36="",$B$38=0),"",N(B36)/$B$38) | E36: =IF(A36="","",IF($B$28>0,MIN(1,N(D36)/$B$28),0)) | F36: =IF(A36="","",N(B36)*$B$28) | G36: =IF(A36="","",N(B36)*($B$28-MIN($B$28,N(D36))))
C37: =IF(OR(A37="",$B$38=0),"",N(B37)/$B$38) | E37: =IF(A37="","",IF($B$28>0,MIN(1,N(D37)/$B$28),0)) | F37: =IF(A37="","",N(B37)*$B$28) | G37: =IF(A37="","",N(B37)*($B$28-MIN($B$28,N(D37))))
A38: Total da etapa (progresso pelas tarefas) | B38: =SUM(B30:B37) -> 60 | E38: =IF(B38>0,SUMPRODUCT(B30:B37,E30:E37)/B38,IF(COUNT(E30:E37)=0,0,SUM(E30:E37)/COUNT(E30:E37))) -> 0 | F38: =SUM(F30:F37) -> 600 | G38: =SUM(G30:G37) -> 600
A39: Unidades concluídas ÷ previstas (menor nº de peças entre as subatividades) | D39: =F28&"/"&B28 -> 0/10 | E39: =IF(B28>0,MIN(1,F28/B28),0) -> 0
A40: ↑ Valores de EXEMPLO (não são dados reais). Substitua pelos seus.
A42: 5. Pontos de Aterramento | E42: Peso no robô | F42: =C392 -> 0 | O42: Concluído | P42: =E53 -> 1
A43: Unidades previstas | B43: =$B$4 -> 10 | E43: Unidades concluídas | F43: =IF(COUNT(E45:E52)=0,0,ROUND(MIN(E45:E52)*B43,0)) -> 10 | O43: Falta | P43: =1-P42 -> 0
A44: Subatividade | B44: Tempo ideal (min) | C44: Peso na etapa | D44: Peças concluídas | E44: % concluído | F44: Tempo total (min) | G44: Tempo que falta (min)
...

Sheet Equipe
A1: Equipe e prazo
A2: Relação simples: dias úteis = horas de trabalho ÷ (pessoas × horas por dia). Considera que as pessoas trabalham em paralelo.
A4: Tempo que falta (h) | B4: =Acompanhamento!G414 -> 27.5
A5: Tempo total da meta (h) | B5: =Acompanhamento!F414 -> 31.666667
A6: Pessoas montando | B6: 1
A7: Horas de trabalho por dia (por pessoa) | B7: 8
A8: Dias úteis restantes | B8: =IF(B6*B7>0,B4/(B6*B7),"") -> 3.4375
A9: Dias úteis para a meta inteira | B9: =IF(B6*B7>0,B5/(B6*B7),"") -> 3.9583333
A11: E se mudar o tamanho da equipe?
A12: Pessoas | B12: Horas por dia (equipe) | C12: Dias úteis restantes
A13: 1 | B13: =A13*$B$7 -> 8 | C13: =IF(B13>0,$B$4/B13,"") -> 3.4375
A14: 2 | B14: =A14*$B$7 -> 16 | C14: =IF(B14>0,$B$4/B14,"") -> 1.71875
A15: 3 | B15: =A15*$B$7 -> 24 | C15: =IF(B15>0,$B$4/B15,"") -> 1.1458333
A16: 4 | B16: =A16*$B$7 -> 32 | C16: =IF(B16>0,$B$4/B16,"") -> 0.859375
A17: 5 | B17: =A17*$B$7 -> 40 | C17: =IF(B17>0,$B$4/B17,"") -> 0.6875
A18: 6 | B18: =A18*$B$7 -> 48 | C18: =IF(B18>0,$B$4/B18,"") -> 0.57291667

Sheet Como funciona
A1: Como cada conta funciona
A2: A coluna 'Exemplo' usa os números que estão agora na primeira etapa da aba Acompanhamento, então muda junto com eles.
A4: Conta | B4: Como é calculada | C4: Exemplo com os números atuais
A5: Peso da subatividade na etapa | B5: Tempo ideal da subatividade ÷ soma dos tempos da etapa. | C5: =IFERROR(Acompanhamento!A18&": "&Acompanhamento!B18&" min ÷ "&Acompanhamento!B23&" min = "&ROUND(Acompanhamento!C18*100,0)&"%","(preencha a primeira etapa)") -> Instalar placa: 100 min ÷ 130 min = 77%
A6: Peso da etapa no robô | B6: Tempo da etapa ÷ tempo de 1 robô (soma de todas as etapas). | C6: =IFERROR(Acompanhamento!A12&": "&Acompanhamento!B23&" min ÷ "&Acompanhamento!B414&" min = "&ROUND(Acompanhamento!C390*100,0)&"%","(preencha a primeira etapa)") -> 3. Montagem do Suporte de Manutenção: 130 min ÷ 190 min = 68%
A7: % concluído da subatividade | B7: Peças concluídas ÷ unidades previstas. Você só digita as peças. | C7: =IFERROR(Acompanhamento!A15&": "&N(Acompanhamento!D15)&" ÷ "&Acompanhamento!B13&" = "&ROUND(Acompanhamento!E15*100,0)&"%","(preencha a primeira etapa)") -> Alinhamento: 5 ÷ 10 = 50%
A8: Progresso da etapa pelas tarefas (Tabela 1) | B8: Soma de (peso × % concluído) das subatividades. Conta as parciais. | C8: =IFERROR(Acompanhamento!A12&": "&ROUND(Acompanhamento!E23*100,1)&"%","(preencha a primeira etapa)") -> 3. Montagem do Suporte de Manutenção: 19.2%
A9: Unidades concluídas da etapa (Tabela 2) | B9: Menor número de peças concluídas entre as subatividades: uma unidade só está pronta quando passou por todas. | C9: =IFERROR(Acompanhamento!A12&": menor nº de peças = "&Acompanhamento!F13&" → "&Acompanhamento!F13&" ÷ "&Acompanhamento!B13&" = "&ROUND(Acompanhamento!E24*100,0)&"%, mesmo com as tarefas em "&ROUND(Acompanhamento!E23*100,0)&"%","(preencha a primeira etapa)") -> 3. Montagem do Suporte de Manutenção: menor nº de peças = 1 → 1 ÷ 10 = 10%, mesmo com as tarefas em 19%
A10: Tempo total da subatividade | B10: Tempo ideal × unidades previstas. | C10: =IFERROR(Acompanhamento!A18&": "&Acompanhamento!B18&" min × "&Acompanhamento!B13&" = "&Acompanhamento!F18&" min","(preencha a primeira etapa)") -> Instalar placa: 100 min × 10 = 1000 min
A11: Tempo que falta | B11: Tempo ideal × (previstas − peças concluídas). | C11: =IFERROR(Acompanhamento!A18&": "&Acompanhamento!B18&" min × ("&Acompanhamento!B13&" − "&N(Acompanhamento!D18)&") = "&Acompanhamento!G18&" min","(preencha a primeira etapa)") -> Instalar placa: 100 min × (10 − 1) = 900 min
A12: Robôs concluídos | B12: Menor número de unidades concluídas entre todas as etapas (um robô só está pronto quando passou por todas). | C12: =IFERROR("Menor valor da coluna Feitas da Tabela 2 = "&Acompanhamento!B377&" de "&Acompanhamento!C377,"(preencha a primeira etapa)") -> Menor valor da coluna Feitas da Tabela 2 = 0 de 10
A13: Dias úteis restantes (aba Equipe) | B13: Tempo que falta ÷ (pessoas × horas por dia). | C13: =IFERROR(ROUND(Equipe!B4,1)&" h ÷ ("&Equipe!B6&" pessoas × "&Equipe!B7&" h) = "&ROUND(Equipe!B8,1)&" dias úteis","(preencha a primeira etapa)") -> 27.5 h ÷ (1 pessoas × 8 h) = 3.4 dias úteis
